# 예외 처리

> 예외(Exception)
>
> 프로그램 코드는 이상이 없으나 실행 중에 불가피하게 발생하는 문제

* try 블록
* except 블록
* else 블록
* finally 블록

```python
try:
    실행할 명령
except 예외 as 변수명:
    오류 처리문
else:
    예외가 발생하지 않을 때의 처리
finally:
    무조건 수행
```

> exception:
>
> 경고: Too broad exception clause = 명확한 Errortype을 명시하지 않아서!
>
> => 해결:  # noinspection PyBroadException
>
> ```python
> dic = {'boy': '소년', 'school': '학교', 'book': '책'}
> # noinspection PyBroadException
> try:
>     print(dic['girl'])
> except:
>     print("찾는 단어가 없습니다.")
> 
> han = dic.get('girl')
> if han is None:
>     print("찾는 단어가 없습니다.")
> else:
>     print(han)
> ```

```python
str = "89점"
try:
    score = int(str)
    print(score)
except:			# try를 실행하는 와중에 발생하는 모든 예외에 대해
    print("예외가 발생했습니다.")
print("작업완료")

# 실행 결과
예외가 발생했습니다.		# 89 '점' -> int 형 변환 불가
작업완료
```

![Screenshot (C:/Users/hajae/OneDrive/%25EB%25B0%2594%25ED%2583%2595%2520%25ED%2599%2594%25EB%25A9%25B4/TIL/images_file/Screenshot%2520(23).png)](../images_file/Screenshot%20(23).png)

> 각 예외에 대해 각각 처리하고 싶을 경우

```python
str = "89"
try:
    score = int(str)
    print(score)
    a = str[5]
except ValueError:
    print("정수의 형식이 잘못되었습니다.")
except IndexError:
    print("첨자 범위를 벗어났습니다.")
print("작업완료")

# 이미 지나간 블록은 다시 찾아가지 않는다 = except 블록을 구현하고 나면 다시 try 블록으로 돌아가지 않는다
```

> except 예외 as 변수명:
>
> 예외 - 처리하고자 하는 에러명
>
> as 변수명 - 사용 시 변수명에 발생된 예외 관련 정보가 입력됨!!

```python
str = "89점"
try:
    score = int(str)
    print(score)
    a = str[5]
except ValueError as e:		
    print(e)
except IndexError as e:
    print(e)
# except (ValueError, IndexError) as e
# 	print(e)
# 로 합칠 수 있음
print("작업완료")

# 실행 결과
invalid literal for int() with base 10: '89점'
작업완료
```



### raise 명령

고의적으로 예외 발생시킴

```python
def calcsum(n):
    if n < 0:
        raise ValueError
    sum = 0
    for i in range(n + 1):
        sum = sum + i
    return sum

try:
    print("~10 =", calcsum(10))
    print("~-5 =", clacsum(-5))
except ValueError:
    print("입력값이 잘못되었습니다.")
```

